Workbook

Sheet B̳ases
A1: Subscriber ID | B1: Name | C1: Plan | D1: Start Date | E1: Auto Renewal | F1: Subscription Price | G1: Subscription Type | H1: EA Play Season Pass | I1: EA Play Season Pass Price | J1: Minecraft Season Pass | K1: Minecraft Season Pass Price | L1: Coupon Value | M1: Total Value
A2: 3231 | B2: João Silva | C2: Ultimate | D2: 45292 | E2: Yes | F2: 15 | G2: Monthly | H2: Yes | I2: 30 | J2: Yes | K2: 20 | L2: 5 | M2: 60
A3: 3232 | B3: Maria Oliveira | C3: Core | D3: 45306 | E3: No | F3: 5 | G3: Annual | H3: No | I3: - | J3: No | K3: 0 | L3: 0 | M3: 5
A4: 3233 | B4: Lucas Fernandes | C4: Standard | D4: 45332 | E4: Yes | F4: 10 | G4: Quarterly | H4: No | I4: - | J4: Yes | K4: 20 | L4: 10 | M4: 20
A5: 3234 | B5: Ana Souza | C5: Ultimate | D5: 45342 | E5: No | F5: 15 | G5: Monthly | H5: Yes | I5: 30 | J5: Yes | K5: 20 | L5: 3 | M5: 62
A6: 3235 | B6: Pedro Gonçalves | C6: Core | D6: 45356 | E6: Yes | F6: 5 | G6: Monthly | H6: No | I6: - | J6: No | K6: 0 | L6: 1 | M6: 4
A7: 3236 | B7: Felipe Costa | C7: Standard | D7: 45353 | E7: No | F7: 10 | G7: Monthly | H7: No | I7: - | J7: Yes | K7: 20 | L7: 2 | M7: 28
A8: 3237 | B8: Camila Ribeiro | C8: Ultimate | D8: 45354 | E8: Yes | F8: 15 | G8: Quarterly | H8: Yes | I8: 30 | J8: Yes | K8: 20 | L8: 10 | M8: 55
A9: 3238 | B9: André Mendes | C9: Core | D9: 45355 | E9: Yes | F9: 5 | G9: Annual | H9: No | I9: - | J9: No | K9: 0 | L9: 0 | M9: 5
A10: 3239 | B10: Sofia Almeida | C10: Ultimate | D10: 45356 | E10: No | F10: 15 | G10: Monthly | H10: Yes | I10: 30 | J10: Yes | K10: 20 | L10: 5 | M10: 60
A11: 3240 | B11: Bruno Martins | C11: Standard | D11: 45357 | E11: Yes | F11: 10 | G11: Quarterly | H11: No | I11: - | J11: Yes | K11: 20 | L11: 15 | M11: 15
A12: 3241 | B12: Rita Castro | C12: Core | D12: 45358 | E12: No | F12: 5 | G12: Monthly | H12: No | I12: - | J12: No | K12: 0 | L12: 1 | M12: 4
A13: 3242 | B13: Marco Túlio | C13: Ultimate | D13: 45359 | E13: Yes | F13: 15 | G13: Annual | H13: Yes | I13: 30 | J13: Yes | K13: 20 | L13: 20 | M13: 45
A14: 3243 | B14: Lívia Silveira | C14: Standard | D14: 45360 | E14: No | F14: 10 | G14: Monthly | H14: No | I14: - | J14: Yes | K14: 20 | L14: 10 | M14: 20
A15: 3244 | B15: Diogo Sousa | C15: Core | D15: 45361 | E15: Yes | F15: 5 | G15: Quarterly | H15: No | I15: - | J15: No | K15: 0 | L15: 0 | M15: 5
A16: 3245 | B16: Fernanda Lima | C16: Ultimate | D16: 45362 | E16: No | F16: 15 | G16: Monthly | H16: Yes | I16: 30 | J16: Yes | K16: 20 | L16: 8 | M16: 57
A17: 3246 | B17: Caio Pereira | C17: Standard | D17: 45363 | E17: Yes | F17: 10 | G17: Annual | H17: No | I17: - | J17: Yes | K17: 20 | L17: 12 | M17: 18
A18: 3247 | B18: Beatriz Gomes | C18: Core | D18: 45364 | E18: No | F18: 5 | G18: Monthly | H18: No | I18: - | J18: No | K18: 0 | L18: 2 | M18: 3
A19: 3248 | B19: Cesar Oliveira | C19: Ultimate | D19: 45365 | E19: Yes | F19: 15 | G19: Quarterly | H19: Yes | I19: 30 | J19: Yes | K19: 20 | L19: 7 | M19: 58
A20: 3249 | B20: Débora Machado | C20: Standard | D20: 45366 | E20: No | F20: 10 | G20: Monthly | H20: No | I20: - | J20: Yes | K20: 20 | L20: 5 | M20: 25
A21: 3250 | B21: Eduardo Vargas | C21: Core | D21: 45367 | E21: Yes | F21: 5 | G21: Annual | H21: No | I21: - | J21: No | K21: 0 | L21: 0 | M21: 5
A22: 3251 | B22: Gabriela Santos | C22: Ultimate | D22: 45368 | E22: No | F22: 15 | G22: Monthly | H22: Yes | I22: 30 | J22: Yes | K22: 20 | L22: 3 | M22: 62
A23: 3252 | B23: Henrique Dias | C23: Standard | D23: 45369 | E23: Yes | F23: 10 | G23: Quarterly | H23: No | I23: - | J23: Yes | K23: 20 | L23: 15 | M23: 15
A24: 3253 | B24: Isabela Moreira | C24: Core | D24: 45370 | E24: No | F24: 5 | G24: Monthly | H24: No | I24: - | J24: No | K24: 0 | L24: 1 | M24: 4
A25: 3254 | B25: Joaquim Barbosa | C25: Ultimate | D25: 45371 | E25: Yes | F25: 15 | G25: Annual | H25: Yes | I25: 30 | J25: Yes | K25: 20 | L25: 20 | M25: 45
A26: 3255 | B26: Lara Rocha | C26: Standard | D26: 45372 | E26: No | F26: 10 | G26: Monthly | H26: No | I26: - | J26: Yes | K26: 20 | L26: 10 | M26: 20
A27: 3256 | B27: Matheus Silva | C27: Core | D27: 45373 | E27: Yes | F27: 5 | G27: Quarterly | H27: No | I27: - | J27: No | K27: 0 | L27: 0 | M27: 5
A28: 3257 | B28: Nicole Costa | C28: Ultimate | D28: 45374 | E28: No | F28: 15 | G28: Monthly | H28: Yes | I28: 30 | J28: Yes | K28: 20 | L28: 5 | M28: 60
A29: 3258 | B29: Otávio Mendonça | C29: Standard | D29: 45375 | E29: Yes | F29: 10 | G29: Annual | H29: No | I29: - | J29: Yes | K29: 20 | L29: 15 | M29: 15
A30: 3259 | B30: Paula Ferreira | C30: Core | D30: 45376 | E30: No | F30: 5 | G30: Monthly | H30: No | I30: - | J30: No | K30: 0 | L30: 1 | M30: 4
A31: 3260 | B31: Raquel Alves | C31: Ultimate | D31: 45377 | E31: Yes | F31: 15 | G31: Quarterly | H31: Yes | I31: 30 | J31: Yes | K31: 20 | L31: 7 | M31: 58
A32: 3261 | B32: Samuel Pires | C32: Standard | D32: 45378 | E32: No | F32: 10 | G32: Monthly | H32: No | I32: - | J32: Yes | K32: 20 | L32: 10 | M32: 20
A33: 3262 | B33: Tânia Barros | C33: Core | D33: 45379 | E33: Yes | F33: 5 | G33: Annual | H33: No | I33: - | J33: No | K33: 0 | L33: 0 | M33: 5
A34: 3263 | B34: Vinicius Lima | C34: Ultimate | D34: 45380 | E34: No | F34: 15 | G34: Monthly | H34: Yes | I34: 30 | J34: Yes | K34: 20 | L34: 3 | M34: 62
A35: 3264 | B35: Yasmin Teixeira | C35: Standard | D35: 45381 | E35: Yes | F35: 10 | G35: Quarterly | H35: No | I35: - | J35: Yes | K35: 20 | L35: 15 | M35: 15
A36: 3265 | B36: Zé Carlos | C36: Core | D36: 45382 | E36: No | F36: 5 | G36: Monthly | H36: No | I36: - | J36: No | K36: 0 | L36: 1 | M36: 4
A37: 3266 | B37: Amanda Nogueira | C37: Core | D37: 45383 | E37: Yes | F37: 5 | G37: Monthly | H37: No | I37: - | J37: No | K37: 0 | L37: 0 | M37: 5
A38: 3267 | B38: Bruno Cavalheiro | C38: Ultimate | D38: 45384 | E38: No | F38: 15 | G38: Quarterly | H38: Yes | I38: 30 | J38: Yes | K38: 20 | L38: 7 | M38: 58
A39: 3268 | B39: Carla Dias | C39: Standard | D39: 45385 | E39: Yes | F39: 10 | G39: Annual | H39: No | I39: - | J39: Yes | K39: 20 | L39: 10 | M39: 20
A40: 3269 | B40: Diego Fontes | C40: Core | D40: 45386 | E40: No | F40: 5 | G40: Quarterly | H40: No | I40: - | J40: No | K40: 0 | L40: 1 | M40: 4
...

Sheet Cálculos
A1: Base tratada e métricas
A3: Subscriber ID | B3: Plan | C3: Start Date | D3: Mês | E3: Nº Mês | F3: Auto_Flag | G3: EA_Flag | H3: MC_Flag | I3: Total Value | J3: Coupon Value | K3: Subscription Type | L3: EA Revenue | M3: Minecraft Revenue
A4: =B̳ases!A2 -> 3231 | B4: =B̳ases!C2 -> Ultimate | C4: =B̳ases!D2 -> 45292 | D4: =TEXT(C4,"mmm") -> jan | E4: =MONTH(C4) -> 1 | F4: =IF(B̳ases!E2="Yes",1,0) -> 1 | G4: =IF(B̳ases!H2="Yes",1,0) -> 1 | H4: =IF(B̳ases!J2="Yes",1,0) -> 1 | I4: =B̳ases!M2 -> 60 | J4: =B̳ases!L2 -> 5 | K4: =B̳ases!G2 -> Monthly | L4: =IFERROR(VALUE(B̳ases!I2),0) -> 30 | M4: =B̳ases!K2 -> 20
A5: =B̳ases!A3 -> 3232 | B5: =B̳ases!C3 -> Core | C5: =B̳ases!D3 -> 45306 | D5: =TEXT(C5,"mmm") -> jan | E5: =MONTH(C5) -> 1 | F5: =IF(B̳ases!E3="Yes",1,0) -> 0 | G5: =IF(B̳ases!H3="Yes",1,0) -> 0 | H5: =IF(B̳ases!J3="Yes",1,0) -> 0 | I5: =B̳ases!M3 -> 5 | J5: =B̳ases!L3 -> 0 | K5: =B̳ases!G3 -> Annual | L5: =IFERROR(VALUE(B̳ases!I3),0) -> 0 | M5: =B̳ases!K3 -> 0
A6: =B̳ases!A4 -> 3233 | B6: =B̳ases!C4 -> Standard | C6: =B̳ases!D4 -> 45332 | D6: =TEXT(C6,"mmm") -> fev | E6: =MONTH(C6) -> 2 | F6: =IF(B̳ases!E4="Yes",1,0) -> 1 | G6: =IF(B̳ases!H4="Yes",1,0) -> 0 | H6: =IF(B̳ases!J4="Yes",1,0) -> 1 | I6: =B̳ases!M4 -> 20 | J6: =B̳ases!L4 -> 10 | K6: =B̳ases!G4 -> Quarterly | L6: =IFERROR(VALUE(B̳ases!I4),0) -> 0 | M6: =B̳ases!K4 -> 20
A7: =B̳ases!A5 -> 3234 | B7: =B̳ases!C5 -> Ultimate | C7: =B̳ases!D5 -> 45342 | D7: =TEXT(C7,"mmm") -> fev | E7: =MONTH(C7) -> 2 | F7: =IF(B̳ases!E5="Yes",1,0) -> 0 | G7: =IF(B̳ases!H5="Yes",1,0) -> 1 | H7: =IF(B̳ases!J5="Yes",1,0) -> 1 | I7: =B̳ases!M5 -> 62 | J7: =B̳ases!L5 -> 3 | K7: =B̳ases!G5 -> Monthly | L7: =IFERROR(VALUE(B̳ases!I5),0) -> 30 | M7: =B̳ases!K5 -> 20
A8: =B̳ases!A6 -> 3235 | B8: =B̳ases!C6 -> Core | C8: =B̳ases!D6 -> 45356 | D8: =TEXT(C8,"mmm") -> mar | E8: =MONTH(C8) -> 3 | F8: =IF(B̳ases!E6="Yes",1,0) -> 1 | G8: =IF(B̳ases!H6="Yes",1,0) -> 0 | H8: =IF(B̳ases!J6="Yes",1,0) -> 0 | I8: =B̳ases!M6 -> 4 | J8: =B̳ases!L6 -> 1 | K8: =B̳ases!G6 -> Monthly | L8: =IFERROR(VALUE(B̳ases!I6),0) -> 0 | M8: =B̳ases!K6 -> 0
A9: =B̳ases!A7 -> 3236 | B9: =B̳ases!C7 -> Standard | C9: =B̳ases!D7 -> 45353 | D9: =TEXT(C9,"mmm") -> mar | E9: =MONTH(C9) -> 3 | F9: =IF(B̳ases!E7="Yes",1,0) -> 0 | G9: =IF(B̳ases!H7="Yes",1,0) -> 0 | H9: =IF(B̳ases!J7="Yes",1,0) -> 1 | I9: =B̳ases!M7 -> 28 | J9: =B̳ases!L7 -> 2 | K9: =B̳ases!G7 -> Monthly | L9: =IFERROR(VALUE(B̳ases!I7),0) -> 0 | M9: =B̳ases!K7 -> 20
A10: =B̳ases!A8 -> 3237 | B10: =B̳ases!C8 -> Ultimate | C10: =B̳ases!D8 -> 45354 | D10: =TEXT(C10,"mmm") -> mar | E10: =MONTH(C10) -> 3 | F10: =IF(B̳ases!E8="Yes",1,0) -> 1 | G10: =IF(B̳ases!H8="Yes",1,0) -> 1 | H10: =IF(B̳ases!J8="Yes",1,0) -> 1 | I10: =B̳ases!M8 -> 55 | J10: =B̳ases!L8 -> 10 | K10: =B̳ases!G8 -> Quarterly | L10: =IFERROR(VALUE(B̳ases!I8),0) -> 30 | M10: =B̳ases!K8 -> 20
A11: =B̳ases!A9 -> 3238 | B11: =B̳ases!C9 -> Core | C11: =B̳ases!D9 -> 45355 | D11: =TEXT(C11,"mmm") -> mar | E11: =MONTH(C11) -> 3 | F11: =IF(B̳ases!E9="Yes",1,0) -> 1 | G11: =IF(B̳ases!H9="Yes",1,0) -> 0 | H11: =IF(B̳ases!J9="Yes",1,0) -> 0 | I11: =B̳ases!M9 -> 5 | J11: =B̳ases!L9 -> 0 | K11: =B̳ases!G9 -> Annual | L11: =IFERROR(VALUE(B̳ases!I9),0) -> 0 | M11: =B̳ases!K9 -> 0
A12: =B̳ases!A10 -> 3239 | B12: =B̳ases!C10 -> Ultimate | C12: =B̳ases!D10 -> 45356 | D12: =TEXT(C12,"mmm") -> mar | E12: =MONTH(C12) -> 3 | F12: =IF(B̳ases!E10="Yes",1,0) -> 0 | G12: =IF(B̳ases!H10="Yes",1,0) -> 1 | H12: =IF(B̳ases!J10="Yes",1,0) -> 1 | I12: =B̳ases!M10 -> 60 | J12: =B̳ases!L10 -> 5 | K12: =B̳ases!G10 -> Monthly | L12: =IFERROR(VALUE(B̳ases!I10),0) -> 30 | M12: =B̳ases!K10 -> 20
A13: =B̳ases!A11 -> 3240 | B13: =B̳ases!C11 -> Standard | C13: =B̳ases!D11 -> 45357 | D13: =TEXT(C13,"mmm") -> mar | E13: =MONTH(C13) -> 3 | F13: =IF(B̳ases!E11="Yes",1,0) -> 1 | G13: =IF(B̳ases!H11="Yes",1,0) -> 0 | H13: =IF(B̳ases!J11="Yes",1,0) -> 1 | I13: =B̳ases!M11 -> 15 | J13: =B̳ases!L11 -> 15 | K13: =B̳ases!G11 -> Quarterly | L13: =IFERROR(VALUE(B̳ases!I11),0) -> 0 | M13: =B̳ases!K11 -> 20
A14: =B̳ases!A12 -> 3241 | B14: =B̳ases!C12 -> Core | C14: =B̳ases!D12 -> 45358 | D14: =TEXT(C14,"mmm") -> mar | E14: =MONTH(C14) -> 3 | F14: =IF(B̳ases!E12="Yes",1,0) -> 0 | G14: =IF(B̳ases!H12="Yes",1,0) -> 0 | H14: =IF(B̳ases!J12="Yes",1,0) -> 0 | I14: =B̳ases!M12 -> 4 | J14: =B̳ases!L12 -> 1 | K14: =B̳ases!G12 -> Monthly | L14: =IFERROR(VALUE(B̳ases!I12),0) -> 0 | M14: =B̳ases!K12 -> 0
A15: =B̳ases!A13 -> 3242 | B15: =B̳ases!C13 -> Ultimate | C15: =B̳ases!D13 -> 45359 | D15: =TEXT(C15,"mmm") -> mar | E15: =MONTH(C15) -> 3 | F15: =IF(B̳ases!E13="Yes",1,0) -> 1 | G15: =IF(B̳ases!H13="Yes",1,0) -> 1 | H15: =IF(B̳ases!J13="Yes",1,0) -> 1 | I15: =B̳ases!M13 -> 45 | J15: =B̳ases!L13 -> 20 | K15: =B̳ases!G13 -> Annual | L15: =IFERROR(VALUE(B̳ases!I13),0) -> 30 | M15: =B̳ases!K13 -> 20
... A298: =B̳ases!A296 -> 3525 | B298: =B̳ases!C296 -> Core | C298: =B̳ases!D296 -> 45642 | D298: =TEXT(C298,"mmm") -> dez | E298: =MONTH(C298) -> 12 | F298: =IF(B̳ases!E296="Yes",1,0) -> 0 | G298: =IF(B̳ases!H296="Yes",1,0) -> 0 | H298: =IF(B̳ases!J296="Yes",1,0) -> 0 | I298: =B̳ases!M296 -> 4 | J298: =B̳ases!L296 -> 1 | K298: =B̳ases!G296 -> Monthly | L298: =IFERROR(VALUE(B̳ases!I296),0) -> 0 | M298: =B̳ases!K296 -> 0
A302: KPIs | D302: Receita por Plano | H302: Assinantes por Tipo
A303: Receita Total | B303: =SUM(I5:I299) -> 7573 | D303: Core | E303: =SUMIF(B5:B299,D303,I5:I299) -> 444 | F303: =COUNTIF(B5:B299,D303) -> 101 | H303: Monthly | I303: =COUNTIF(K5:K299,H303) -> 138
A304: Total de Assinantes | B304: =COUNTA(A5:A299) -> 294 | D304: Standard | E304: =SUMIF(B5:B299,D304,I5:I299) -> 1801 | F304: =COUNTIF(B5:B299,D304) -> 96 | H304: Quarterly | I304: =COUNTIF(K5:K299,H304) -> 85
A305: Ticket Médio | B305: =AVERAGE(I5:I299) -> 25.758503 | D305: Ultimate | E305: =SUMIF(B5:B299,D305,I5:I299) -> 5328 | F305: =COUNTIF(B5:B299,D305) -> 97 | H305: Annual | I305: =COUNTIF(K5:K299,H305) -> 71
A306: Cupons Concedidos | B306: =SUM(J5:J299) -> 2117
A307: % Auto Renewal | B307: =AVERAGE(F5:F299) -> 0.5
A308: Receita EA Play | B308: =SUM(L5:L299) -> 2910
A309: Receita Minecraft | B309: =SUM(M5:M299) -> 3860
A312: Receita Mensal | E312: Extras e Renovação
A313: Jan | B313: 1 | C313: =SUMIF(E5:E299,B313,I5:I299) -> 5 | E313: EA Play | F313: =SUM(L5:L299) -> 2910
A314: Feb | B314: 2 | C314: =SUMIF(E5:E299,B314,I5:I299) -> 82 | E314: Minecraft | F314: =SUM(M5:M299) -> 3860
A315: Mar | B315: 3 | C315: =SUMIF(E5:E299,B315,I5:I299) -> 801 | E315: Auto Yes | F315: =COUNTIF(F5:F299,1) -> 147
A316: Apr | B316: 4 | C316: =SUMIF(E5:E299,B316,I5:I299) -> 782 | E316: Auto No | F316: =COUNTIF(F5:F299,0) -> 147
A317: May | B317: 5 | C317: =SUMIF(E5:E299,B317,I5:I299) -> 777
A318: Jun | B318: 6 | C318: =SUMIF(E5:E299,B318,I5:I299) -> 770
A319: Jul | B319: 7 | C319: =SUMIF(E5:E299,B319,I5:I299) -> 784
A320: Aug | B320: 8 | C320: =SUMIF(E5:E299,B320,I5:I299) -> 787
A321: Sep | B321: 9 | C321: =SUMIF(E5:E299,B321,I5:I299) -> 780
A322: Oct | B322: 10 | C322: =SUMIF(E5:E299,B322,I5:I299) -> 832
A323: Nov | B323: 11 | C323: =SUMIF(E5:E299,B323,I5:I299) -> 784
A324: Dec | B324: 12 | C324: =SUMIF(E5:E299,B324,I5:I299) -> 389

Sheet Dashboard
C2: XBOX GAME PASS SALES DASHBOARD
C4: Painel executivo com foco em receita, planos, assinatura e monetização de extras
C7: Receita Total | F7: Assinantes | I7: Ticket Médio | L7: Auto Renewal
C8: R$ 7.633 | F8: 295 | I8: R$ 25,87 | L8: 50,2%
C10: Valor final pago pelos clientes | F10: Total de registros válidos | I10: Receita média por assinatura | L10: Clientes com renovação ativa
C12: Cupons | F12: Plano Líder | I12: EA Play | L12: Minecraft
C13: R$ 2.122 | F13: Ultimate | I13: R$ 2.940 | L13: R$ 3.880
C15: Descontos concedidos | F15: Maior receita no período | I15: Receita do extra EA Play | L15: Receita do add-on Minecraft
C18: Receita ao longo do ano | J18: Insights | M18: Receita por plano
J19: • O plano Ultimate concentra a maior parte da receita. • A taxa de auto renewal está em 50%. • Minecraft gera R$ 3.880, acima de EA Play. • Outubro foi o pico de faturamento mensal.
C31: Mix de assinaturas | H31: Monetização de extras | M31: Renovação automática
